Workbook
Name Active_Client: Control_Panel!$C$11
Name Active_Year: Control_Panel!$C$8
Name Activity_Type: Dropdown_Lists!$G$4:$G$5
Name AdjToIncome: INDIRECT("Y"&Active_Year&"!$N$14")
Name Adjustment_Docs: Dropdown_Lists!$E$35:$E$39
Name Adjustment_Profiles: Dropdown_Lists!$E$19:$E$23
Name AGI: INDIRECT("Y"&Active_Year&"!$N$15")
Name BI_ACTIVE_NONSE: INDIRECT("Y"&Active_Year&"!$J$27")
Name BI_PASSIVE: INDIRECT("Y"&Active_Year&"!$J$28")
Name BI_SE_SUBJECT: INDIRECT("Y"&Active_Year&"!$J$26")
Name Bucket: Dropdown_Lists!$A$4:$A$11
Name BusinessIncome_Docs: Dropdown_Lists!$A$35:$A$41
Name BusinessIncome_Profiles: Dropdown_Lists!$A$19:$A$27
Name BusinessLoss: INDIRECT("Y"&Active_Year&"!$J$42")
Name CapitalGains_Docs: Dropdown_Lists!$D$35:$D$38
Name CapitalGains_Profiles: Dropdown_Lists!$D$19:$D$23
Name CG_LT: INDIRECT("Y"&Active_Year&"!$J$31")
Name CG_ST: INDIRECT("Y"&Active_Year&"!$J$32")
Name Credit_Docs: Dropdown_Lists!$G$35:$G$37
Name Credit_Profiles: Dropdown_Lists!$G$19:$G$21
Name Drill_Line: INDIRECT("Y"&Active_Year&"!$I$49")
Name Filing_Status: Control_Panel!$C$15
Name InvestmentIncome_Docs: Dropdown_Lists!$C$35:$C$37
Name InvestmentIncome_Profiles: Dropdown_Lists!$C$19:$C$22
Name IsSSTB: INDIRECT("Y"&Active_Year&"!$J$45")
Name Itemized_Docs: Dropdown_Lists!$F$35:$F$38
Name Itemized_Profiles: Dropdown_Lists!$F$19:$F$22
Name Line_1z_Wages: INDIRECT("Y"&Active_Year&"!$N$6")
Name Line_2a_TaxExempt: INDIRECT("Y"&Active_Year&"!$N$7")
Name Line_2b_TaxInt: INDIRECT("Y"&Active_Year&"!$N$8")
Name Line_3a_QualDiv: INDIRECT("Y"&Active_Year&"!$N$9")
Name Line_3b_OrdDiv: INDIRECT("Y"&Active_Year&"!$N$10")
Name Line_7_CapGain: INDIRECT("Y"&Active_Year&"!$N$11")
Name Line_8_OtherInc: INDIRECT("Y"&Active_Year&"!$N$12")
Name MAGI: INDIRECT("Y"&Active_Year&"!$J$38")
Name NetSEIncome: INDIRECT("Y"&Active_Year&"!$J$43")
Name NII: INDIRECT("Y"&Active_Year&"!$J$39")
Name NIIT_Class: Dropdown_Lists!$C$4:$C$7
Name NOL_Carryforward: INDIRECT("Y"&Active_Year&"!$J$46")
Name OrdIncome: INDIRECT("Y"&Active_Year&"!$J$37")
Name Payment_Docs: Dropdown_Lists!$H$35:$H$36
Name Payment_Profiles: Dropdown_Lists!$H$19:$H$20
Name Provenance: Dropdown_Lists!$D$4:$D$13
Name QBI_Deduction: INDIRECT("Y"&Active_Year&"!$N$17")
Name QBI_Income: INDIRECT("Y"&Active_Year&"!$J$40")
Name QUAL_DIV: INDIRECT("Y"&Active_Year&"!$J$30")
Name SEC1250: INDIRECT("Y"&Active_Year&"!$J$33")
Name Slicer_Activity_Type: #N/A
Name Slicer_Activity_Type1: #N/A
Name Slicer_Activity_Type2: #N/A
Name Slicer_Activity_Type3: #N/A
Name Slicer_Bucket: #N/A
Name Slicer_Bucket1: #N/A
Name Slicer_ClientID: #N/A
Name Slicer_ClientID1: #N/A
Name Slicer_NIIT_Class: #N/A
Name Slicer_QBI_Eligible: #N/A
Name Slicer_SE_Subject: #N/A
Name Slicer_Year: #N/A
Name Slicer_Year1: #N/A

Sheet Control_Panel
B2: TAX WORKBOOK — CONTROL PANEL
B3: Settings, navigation, and input reference — start here.
B5: ▸ SETTINGS
B7: PLAN STATUS
B8: Plan Year | C8: 2025
B9: Plan Maturity | C9: Standard Assumptions
B10: Engagement Leader | C10: TBD
B11: Active Client | C11: SAMPLE
B12: Last Refresh | C12: 46161
B14: TAX PROFILE
B15: Filing Status | C15: MFJ
B16: State of Residence | C16: UT
B17: Taxpayer Age | C17: 42
B18: Spouse Age | C18: 40
B19: Dependent Children | C19: 2
B20: REPS Qualified | C20: No
B21: Business is SSTB? | C21: No
B22: ▸ HOUSEHOLD DETAILS
B23: Taxpayer Name | C23: TAXPAYER | D23: Used in Deliverable header
B24: Spouse Name | C24: SPOUSE | D24: Only used if Filing_Status = MFJ
B25: Taxpayer 65+ | C25: No | D25: Adds $1,550 to standard deduction (2024)
B26: Spouse 65+ | C26: No | D26: Adds $1,550 to standard deduction (2024)
B27: Taxpayer Blind | C27: No | D27: Adds $1,550 to standard deduction (2024)
B28: Spouse Blind | C28: No | D28: Adds $1,550 to standard deduction (2024)
B29: Dep — CTC Qualifying | C29: 2 | D29: Children under 17 — $2,000 CTC each
B30: Dep — ODC Qualifying | C30: 0 | D30: Other dependents — $500 ODC each
B31: Self-Employed Health Ins | C31: No | D31: Eligible to deduct SE health ins above-line
B32: Itemize Override | C32: Auto | D32: Auto / Force Itemize / Force Standard
B33: Prior Year Total Tax | C33: 0 | D33: For 110% safe harbor calc
B35: ▸ ACTIVE YEAR SNAPSHOT
B36: AGI | C36: {=TEXT(AGI,"$#,##0")}
B37: Taxable Income | C37: {=TEXT(TaxableIncome,"$#,##0")}
B38: Effective Rate | C38: {=TEXT(IFERROR(INDIRECT("Y"&Active_Year&"!I130"),0),"0.0%")}
B39: Total Tax | C39: {=TEXT(IFERROR(INDIRECT("Y"&Active_Year&"!I129"),0),"$#,##0")}
B40: QBI Deduction | C40: {=TEXT(QBI_Deduction,"($#,##0)")}
B42: ▸ NAVIGATION
B44: INPUT / CONFIG
B45: =HYPERLINK("#Master_Inputs!A1", "Master_Inputs") | C45: Baseline income/deductions + committed strategies
B46: =HYPERLINK("#AsFiled!A1", "AsFiled") | C46: Filed return data by year for PY reconciliation
B47: =HYPERLINK("#Carryovers!A1", "Carryovers") | C47: PAL, CL, NOL manual inputs + calculator
...

Sheet Master_Inputs
A1: MASTER INPUTS — committed baseline source-input items (one row per source document per year)
A2: Adjustments and strategies live on the year sheet. Master is just where baseline data lives.
A4: InputID | B4: Year | C4: ClientID | D4: ClientName | E4: Bucket | F4: Treatment_Profile | G4: Source_Document | H4: Activity_Type | I4: Provenance | J4: Payor | K4: Baseline_Amount | L4: Helper_Amount | M4: Helper_Treatment | N4: SE_Subject | O4: NIIT_Class | P4: QBI_Eligible | Q4: Primary_Line | R4: Consider | S4: Notes
A5: CED|2024|Wages|01 | B5: 2024 | C5: CEDILLO | D5: Ron Cedillo | E5: Wages | F5: W2_SCorpOwner | G5: W-2 | H5: Baseline | I5: PBC - Reviewed | J5: Acme S-Corp | K5: 153648 | L5: 0 | M5: OWNER_PAY | N5: No | O5: Active | P5: No | Q5: 1z | R5: Owner reasonable comp
A6: CED|2024|BI|01 | B6: 2024 | C6: CEDILLO | D6: Ron Cedillo | E6: Business Income | F6: K1_PTP_Passive | G6: K-1 | H6: Baseline | I6: PBC - Reviewed | J6: Cedillo Partnership | K6: -100766 | L6: 0 | M6: K1_SPLIT | N6: No | O6: Passive | P6: Yes | Q6: 8 | R6: Passive loss
A7: CED|2024|II|01 | B7: 2024 | C7: CEDILLO | D7: Ron Cedillo | E7: Investment Income | F7: Div_Ordinary | G7: 1099-DIV | H7: Baseline | I7: PBC - Reviewed | J7: Brokerage | K7: 25922 | L7: 0 | M7: QUAL_DIV | N7: No | O7: Portfolio | P7: No | Q7: 3b | R7: All non-qualified
A8: CED|2024|CG|01 | B8: 2024 | C8: CEDILLO | D8: Ron Cedillo | E8: Capital Gains | F8: LTCG_Stock | G8: 1099-B | H8: Baseline | I8: PBC - Reviewed | J8: Brokerage | K8: 14487 | L8: 0 | M8: LTCG_SPLIT | N8: No | O8: Portfolio | P8: No | Q8: 7 | R8: All long-term
A9: SAM|2025|Wages|01 | B9: 2025 | C9: SAMPLE | D9: Sample Client | E9: Wages | F9: W2_SCorpOwner | G9: W-2 | H9: Baseline | I9: Estimate - Preparer | J9: SampleCo S-Corp | K9: 100000 | L9: 100000 | M9: OWNER_PAY | N9: No | O9: Active | P9: No | Q9: 1z | R9: Owner reasonable comp
A10: SAM|2025|BI|01 | B10: 2025 | C10: SAMPLE | D10: Sample Client | E10: Business Income | F10: K1_SCorp_Active | G10: K-1 | H10: Baseline | I10: PY Rolled Forward | J10: SampleCo S-Corp K-1 | K10: 200000 | L10: 0 | M10: K1_SPLIT | N10: No | O10: Active | P10: Yes | Q10: 8 | R10: Active S-corp K-1
A11: SAM|2025|II_Div|01 | B11: 2025 | C11: SAMPLE | D11: Sample Client | E11: Investment Income | F11: Div_Qualified | G11: 1099-DIV | H11: Baseline | I11: PBC - Received | J11: Brokerage | K11: 10000 | L11: 7000 | M11: QUAL_DIV | N11: No | O11: Portfolio | P11: No | Q11: 3b | R11: $7K qualified
A12: SAM|2025|II_Int|01 | B12: 2025 | C12: SAMPLE | D12: Sample Client | E12: Investment Income | F12: Int_Taxable | G12: 1099-INT | H12: Baseline | I12: PBC - Received | J12: Brokerage | K12: 500 | L12: 0 | M12: NONE | N12: No | O12: Portfolio | P12: No | Q12: 2b | R12: All taxable
A13: SAM|2025|CG|01 | B13: 2025 | C13: SAMPLE | D13: Sample Client | E13: Capital Gains | F13: LTCG_Stock | G13: 1099-B | H13: Baseline | I13: PBC - Requested | J13: Brokerage | K13: 25000 | L13: 0 | M13: LTCG_SPLIT | N13: No | O13: Portfolio | P13: No | Q13: 7 | R13: All long-term
A14: SAM|2025|Itm|01 | B14: 2025 | C14: SAMPLE | D14: Sample Client | E14: Itemized | F14: Itm_SALT | G14: Property Tax Receipt | H14: Baseline | I14: PBC - Received | K14: -10000 | L14: 0 | M14: SALT | N14: No | O14: N/A | P14: No | Q14: 12 | R14: SALT cap
A15: SAM|2025|Strategy|WageOpt|01 | B15: 2025 | C15: SAMPLE | D15: Sample Client | E15: Wages | F15: W2_SCorpOwner | H15: Strategy | I15: Planning | J15: SampleCo S-Corp | K15: -25000 | L15: 0 | M15: OWNER_PAY | N15: No | O15: Active | P15: No | Q15: 1z | R15: Reduce owner W-2 by $25K | S15: STR-001 Committed
A16: SAM|2025|Strategy|WageOpt|02 | B16: 2025 | C16: SAMPLE | D16: Sample Client | E16: Business Income | F16: K1_SCorp_Active | H16: Strategy | I16: Planning | J16: SampleCo S-Corp K-1 | K16: 25000 | L16: 0 | M16: K1_SPLIT | N16: No | O16: Active | P16: Yes | Q16: 8 | R16: Corresponding K-1 increase from wage reduction | S16: STR-001 Committed
A17: SAM|2025|Strategy|HSA|01 | B17: 2025 | C17: SAMPLE | D17: Sample Client | E17: Adjustment | F17: Adj_HSA | H17: Strategy | I17: Planning | K17: -8550 | L17: 0 | M17: NONE | N17: No | O17: N/A | P17: No | Q17: 10 | R17: Family HSA max contribution | S17: STR-002 Committed
A18: SAM|2025|Strategy|CostSeg|01 | B18: 2025 | C18: SAMPLE | D18: Sample Client | E18: Business Income | F18: SchE_Rental | H18: Strategy | I18: Planning | J18: 123 Main St, Salt Lake City | K18: -80000 | L18: 0 | M18: PASSIVE | N18: No | O18: Passive | P18: No | Q18: 8 | R18: Cost seg accelerated depreciation | S18: STR-005 Committed

Sheet AsFiled
B2: ASFILED — Filed Tax Return Data
B3: Filed return amounts by 1040 line. Use Year column filter to view one year at a time. Add rows per year as needed. PY_Recon uses SUMIFS against this table.
B5: InputID | C5: Year | D5: ClientID | E5: ClientName | F5: Bucket | G5: Treatment_Profile | H5: Source_Document | I5: Provenance | J5: Payor | K5: Filed_Amount | L5: Helper_Amount | M5: Helper_Treatment | N5: Primary_Line | O5: Notes
B6: CED|2024|AF|Wages|01 | C6: 2024 | D6: CEDILLO | E6: Ron Cedillo | F6: Wages | G6: W2_SCorpOwner | H6: Filed 1040 | I6: Filed Return | J6: Acme S-Corp | K6: 153648 | L6: 0 | M6: OWNER_PAY | N6: 1z | O6: Per filed Form 1040 Line 1z
B7: CED|2024|AF|BI|01 | C7: 2024 | D7: CEDILLO | E7: Ron Cedillo | F7: Business Income | G7: K1_PTP_Passive | H7: Filed 1040 | I7: Filed Return | J7: Cedillo Partnership | K7: -100766 | L7: 0 | M7: K1_SPLIT | N7: 8 | O7: Per filed Sch 1 / K-1
B8: CED|2024|AF|II|01 | C8: 2024 | D8: CEDILLO | E8: Ron Cedillo | F8: Investment Income | G8: Div_Ordinary | H8: Filed 1040 | I8: Filed Return | J8: Brokerage | K8: 25922 | L8: 0 | M8: QUAL_DIV | N8: 3b | O8: Per filed 1040 Line 3b
B9: CED|2024|AF|CG|01 | C9: 2024 | D9: CEDILLO | E9: Ron Cedillo | F9: Capital Gains | G9: LTCG_Stock | H9: Filed 1040 | I9: Filed Return | J9: Brokerage | K9: 14487 | L9: 0 | M9: LTCG_SPLIT | N9: 7 | O9: Per filed 1040 Line 7
B10: PLACEHOLDER|2023 | C10: 2023 | I10: Estimate | K10: 0 | L10: 0 | O10: Enter 2023 filed data here — add rows as needed
B11: PLACEHOLDER|2025 | C11: 2025 | I11: Estimate | K11: 0 | L11: 0 | O11: Enter 2025 filed data here — add rows as needed
B12: PLACEHOLDER|2026 | C12: 2026 | I12: Estimate | K12: 0 | L12: 0 | O12: Enter 2026 filed data here — add rows as needed
B13: PLACEHOLDER|2027 | C13: 2027 | I13: Estimate | K13: 0 | L13: 0 | O13: Enter 2027 filed data here — add rows as needed
B14: PLACEHOLDER|2028 | C14: 2028 | I14: Estimate | K14: 0 | L14: 0 | O14: Enter 2028 filed data here — add rows as needed

Sheet Tax_Plan_Dashboard
B2: TAX PLAN DASHBOARD
B3: Pick any year from the dropdown below — the entire dashboard updates. Type =Active_Year in C4 to sync with Control_Panel.
B4: Year: | C4: 2025 | D4: (Active_Year on Control_Panel: | E4: =Active_Year
B6: ▸ BOX 1 — THE HEADLINE | G6: ▸ BOX 2 — STRATEGY-BY-STRATEGY MARGINAL SAVINGS
B7: Metric | C7: Without Planning | D7: With Planning | E7: Δ Savings | G7: # | H7: Strategy | I7: Status | J7: Amount | K7: Marginal Δ
B8: Total Income | C8: =INDIRECT("Y"&$C$4&"!J125") | D8: =INDIRECT("Y"&$C$4&"!K125") | E8: =C8-D8 | G8: #1 | H8: =INDIRECT("Y"&$C$4&"!B6") | I8: =INDIRECT("Y"&$C$4&"!E6") | J8: =IFERROR(INDIRECT("Y"&$C$4&"!D6"),0) | K8: =IF(OR(I8="Committed",I8="Implemented"),-J8*0.32,0)
B9: Taxable Income | C9: =INDIRECT("Y"&$C$4&"!J94") | D9: =INDIRECT("Y"&$C$4&"!K94") | E9: =C9-D9 | G9: #2 | H9: =INDIRECT("Y"&$C$4&"!B7") | I9: =INDIRECT("Y"&$C$4&"!E7") | J9: =IFERROR(INDIRECT("Y"&$C$4&"!D7"),0) | K9: =IF(OR(I9="Committed",I9="Implemented"),-J9*0.32,0)
B10: Federal Income Tax | C10: =INDIRECT("Y"&$C$4&"!J97")+INDIRECT("Y"&$C$4&"!J107") | D10: =INDIRECT("Y"&$C$4&"!K97")+INDIRECT("Y"&$C$4&"!K107") | E10: =C10-D10 | G10: #3 | H10: =INDIRECT("Y"&$C$4&"!B8") | I10: =INDIRECT("Y"&$C$4&"!E8") | J10: =IFERROR(INDIRECT("Y"&$C$4&"!D8"),0) | K10: =IF(OR(I10="Committed",I10="Implemented"),-J10*0.32,0)
B11: Payroll & SE Taxes | C11: =INDIRECT("Y"&$C$4&"!J80")+INDIRECT("Y"&$C$4&"!J91") | D11: =INDIRECT("Y"&$C$4&"!K80")+INDIRECT("Y"&$C$4&"!K91") | E11: =C11-D11 | G11: #4 | H11: =INDIRECT("Y"&$C$4&"!B9") | I11: =INDIRECT("Y"&$C$4&"!E9") | J11: =IFERROR(INDIRECT("Y"&$C$4&"!D9"),0) | K11: =IF(OR(I11="Committed",I11="Implemented"),-J11*0.32,0)
B12: NIIT | C12: =INDIRECT("Y"&$C$4&"!J114") | D12: =INDIRECT("Y"&$C$4&"!K114") | E12: =C12-D12 | G12: #5 | H12: =INDIRECT("Y"&$C$4&"!B10") | I12: =INDIRECT("Y"&$C$4&"!E10") | J12: =IFERROR(INDIRECT("Y"&$C$4&"!D10"),0) | K12: =IF(OR(I12="Committed",I12="Implemented"),-J12*0.32,0)
B13: Total Tax | C13: =INDIRECT("Y"&$C$4&"!J133") | D13: =INDIRECT("Y"&$C$4&"!K133") | E13: =C13-D13 | G13: #6 | H13: =INDIRECT("Y"&$C$4&"!B11") | I13: =INDIRECT("Y"&$C$4&"!E11") | J13: =IFERROR(INDIRECT("Y"&$C$4&"!D11"),0) | K13: =IF(OR(I13="Committed",I13="Implemented"),-J13*0.32,0)
B14: Effective Rate | C14: =INDIRECT("Y"&$C$4&"!J134") | D14: =INDIRECT("Y"&$C$4&"!K134") | E14: =C14-D14 | G14: #7 | H14: =INDIRECT("Y"&$C$4&"!B12") | I14: =INDIRECT("Y"&$C$4&"!E12") | J14: =IFERROR(INDIRECT("Y"&$C$4&"!D12"),0) | K14: =IF(OR(I14="Committed",I14="Implemented"),-J14*0.32,0)
B15: After-Tax Cash | C15: =C8-C13 | D15: =D8-D13 | E15: =D15-C15 | G15: #8 | H15: =INDIRECT("Y"&$C$4&"!B13") | I15: =INDIRECT("Y"&$C$4&"!E13") | J15: =IFERROR(INDIRECT("Y"&$C$4&"!D13"),0) | K15: =IF(OR(I15="Committed",I15="Implemented"),-J15*0.32,0)
G16: #9 | H16: =INDIRECT("Y"&$C$4&"!B14") | I16: =INDIRECT("Y"&$C$4&"!E14") | J16: =IFERROR(INDIRECT("Y"&$C$4&"!D14"),0) | K16: =IF(OR(I16="Committed",I16="Implemented"),-J16*0.32,0)
B17: ▸ BOX 3 — TAX PLAN EXECUTION | G17: #10 | H17: =INDIRECT("Y"&$C$4&"!B15") | I17: =INDIRECT("Y"&$C$4&"!E15") | J17: =IFERROR(INDIRECT("Y"&$C$4&"!D15"),0) | K17: =IF(OR(I17="Committed",I17="Implemented"),-J17*0.32,0)
B18: Metric | C18: Without | D18: With | E18: Δ | G18: #11 | H18: =INDIRECT("Y"&$C$4&"!B16") | I18: =INDIRECT("Y"&$C$4&"!E16") | J18: =IFERROR(INDIRECT("Y"&$C$4&"!D16"),0) | K18: =IF(OR(I18="Committed",I18="Implemented"),-J18*0.32,0)
B19: Federal Income Tax | C19: =C10 | D19: =D10 | E19: =C19-D19 | G19: #12 | H19: =INDIRECT("Y"&$C$4&"!B17") | I19: =INDIRECT("Y"&$C$4&"!E17") | J19: =IFERROR(INDIRECT("Y"&$C$4&"!D17"),0) | K19: =IF(OR(I19="Committed",I19="Implemented"),-J19*0.32,0)
B20: Total Tax (all components) | C20: =C13 | D20: =D13 | E20: =C20-D20 | G20: #13 | H20: =INDIRECT("Y"&$C$4&"!B18") | I20: =INDIRECT("Y"&$C$4&"!E18") | J20: =IFERROR(INDIRECT("Y"&$C$4&"!D18"),0) | K20: =IF(OR(I20="Committed",I20="Implemented"),-J20*0.32,0)
B21: Effective Rate | C21: =C14 | D21: =D14 | E21: =C21-D21 | G21: #14 | H21: =INDIRECT("Y"&$C$4&"!B19") | I21: =INDIRECT("Y"&$C$4&"!E19") | J21: =IFERROR(INDIRECT("Y"&$C$4&"!D19"),0) | K21: =IF(OR(I21="Committed",I21="Implemented"),-J21*0.32,0)
B22: TOTAL TAX SAVED | E22: =E20 | G22: #15 | H22: =INDIRECT("Y"&$C$4&"!B20") | I22: =INDIRECT("Y"&$C$4&"!E20") | J22: =IFERROR(INDIRECT("Y"&$C$4&"!D20"),0) | K22: =IF(OR(I22="Committed",I22="Implemented"),-J22*0.32,0)
H23: Subtotal — Direct Strategy Savings | K23: =SUM(K8:K22)
H24: Plan Synergy Adjustment (Canon v1.4 est.) | K24: 0
H25: PLAN TOTAL | K25: =K23+K24
G27: Marginal Δ = -Amount × 32% approx. Replace with KISS LAMBDA exact recalc when LAMBDAs install (Phase 3c).
G30: ▸ BOX 4 — STRATEGY CHECKLIST + TAKE-HOME CASH
H31: Take-Home Cash (Without) | K31: =C15
H32: Take-Home Cash (With) | K32: =D15
H33: Δ Take-Home (annual) | K33: =E15
H34: Effective Tax % | K34: =D14
G36: Status | H36: # | I36: Strategy | K36: Status Text
G37: =IF(INDIRECT("Y"&$C$4&"!E6")="Implemented","☑",IF(INDIRECT("Y"&$C$4&"!E6")="Committed","☑",IF(INDIRECT("Y"&$C$4&"!E6")="Approved","▣",IF(INDIRECT("Y"&$C$4&"!E6")="Proposed","☐","─")))) | H37: #1 | I37: =INDIRECT("Y"&$C$4&"!B6") | K37: =INDIRECT("Y"&$C$4&"!E6")
G38: =IF(INDIRECT("Y"&$C$4&"!E7")="Implemented","☑",IF(INDIRECT("Y"&$C$4&"!E7")="Committed","☑",IF(INDIRECT("Y"&$C$4&"!E7")="Approved","▣",IF(INDIRECT("Y"&$C$4&"!E7")="Proposed","☐","─")))) | H38: #2 | I38: =INDIRECT("Y"&$C$4&"!B7") | K38: =INDIRECT("Y"&$C$4&"!E7")
G39: =IF(INDIRECT("Y"&$C$4&"!E8")="Implemented","☑",IF(INDIRECT("Y"&$C$4&"!E8")="Committed","☑",IF(INDIRECT("Y"&$C$4&"!E8")="Approved","▣",IF(INDIRECT("Y"&$C$4&"!E8")="Proposed","☐","─")))) | H39: #3 | I39: =INDIRECT("Y"&$C$4&"!B8") | K39: =INDIRECT("Y"&$C$4&"!E8")
G40: =IF(INDIRECT("Y"&$C$4&"!E9")="Implemented","☑",IF(INDIRECT("Y"&$C$4&"!E9")="Committed","☑",IF(INDIRECT("Y"&$C$4&"!E9")="Approved","▣",IF(INDIRECT("Y"&$C$4&"!E9")="Proposed","☐","─")))) | H40: #4 | I40: =INDIRECT("Y"&$C$4&"!B9") | K40: =INDIRECT("Y"&$C$4&"!E9")
G41: =IF(INDIRECT("Y"&$C$4&"!E10")="Implemented","☑",IF(INDIRECT("Y"&$C$4&"!E10")="Committed","☑",IF(INDIRECT("Y"&$C$4&"!E10")="Approved","▣",IF(INDIRECT("Y"&$C$4&"!E10")="Proposed","☐","─")))) | H41: #5 | I41: =INDIRECT("Y"&$C$4&"!B10") | K41: =INDIRECT("Y"&$C$4&"!E10")
G42: =IF(INDIRECT("Y"&$C$4&"!E11")="Implemented","☑",IF(INDIRECT("Y"&$C$4&"!E11")="Committed","☑",IF(INDIRECT("Y"&$C$4&"!E11")="Approved","▣",IF(INDIRECT("Y"&$C$4&"!E11")="Proposed","☐","─")))) | H42: #6 | I42: =INDIRECT("Y"&$C$4&"!B11") | K42: =INDIRECT("Y"&$C$4&"!E11")
G43: =IF(INDIRECT("Y"&$C$4&"!E12")="Implemented","☑",IF(INDIRECT("Y"&$C$4&"!E12")="Committed","☑",IF(INDIRECT("Y"&$C$4&"!E12")="Approved","▣",IF(INDIRECT("Y"&$C$4&"!E12")="Proposed","☐","─")))) | H43: #7 | I43: =INDIRECT("Y"&$C$4&"!B12") | K43: =INDIRECT("Y"&$C$4&"!E12")
G44: =IF(INDIRECT("Y"&$C$4&"!E13")="Implemented","☑",IF(INDIRECT("Y"&$C$4&"!E13")="Committed","☑",IF(INDIRECT("Y"&$C$4&"!E13")="Approved","▣",IF(INDIRECT("Y"&$C$4&"!E13")="Proposed","☐","─")))) | H44: #8 | I44: =INDIRECT("Y"&$C$4&"!B13") | K44: =INDIRECT("Y"&$C$4&"!E13")
G45: =IF(INDIRECT("Y"&$C$4&"!E14")="Implemented","☑",IF(INDIRECT("Y"&$C$4&"!E14")="Committed","☑",IF(INDIRECT("Y"&$C$4&"!E14")="Approved","▣",IF(INDIRECT("Y"&$C$4&"!E14")="Proposed","☐","─")))) | H45: #9 | I45: =INDIRECT("Y"&$C$4&"!B14") | K45: =INDIRECT("Y"&$C$4&"!E14")
G46: =IF(INDIRECT("Y"&$C$4&"!E15")="Implemented","☑",IF(INDIRECT("Y"&$C$4&"!E15")="Committed","☑",IF(INDIRECT("Y"&$C$4&"!E15")="Approved","▣",IF(INDIRECT("Y"&$C$4&"!E15")="Proposed","☐","─")))) | H46: #10 | I46: =INDIRECT("Y"&$C$4&"!B15") | K46: =INDIRECT("Y"&$C$4&"!E15")
...

Sheet Deliverable
B1: ACCRUITY
B2: TAX PLAN — CLIENT DELIVERABLE
B3: =Active_Client&" — Plan Year "&Active_Year
B4: =Filing_Status&" · Last Refresh: "&TEXT(NOW(),"yyyy-mm-dd")
B7: SECTION 1 — HEADLINE SUMMARY
B9: Your tax bill WITHOUT Accruity planning | E9: =INDIRECT("Y"&Active_Year&"!J133")
B10: Your tax bill WITH Accruity planning | E10: =INDIRECT("Y"&Active_Year&"!K133")
B12: ANNUAL TAX SAVINGS | E12: =E9-E10
B14: Effective tax rate | E14: =TEXT(INDIRECT("Y"&Active_Year&"!J134"),"0.00%")&" → "&TEXT(INDIRECT("Y"&Active_Year&"!K134"),"0.00%")
B17: SECTION 2 — INCOME WATERFALL
B19: Description | C19: Without Planning | D19: With Planning | E19: Variance | F19: Notes
B20: Wages (Line 1z) | C20: =INDIRECT("Y"&Active_Year&"!J6") | D20: =INDIRECT("Y"&Active_Year&"!O6") | E20: =D20-C20 | F20: Owner W-2 + 3rd-party
B21: Tax-exempt interest (info, 2a) | C21: =INDIRECT("Y"&Active_Year&"!J7") | D21: =INDIRECT("Y"&Active_Year&"!O7") | E21: =D21-C21 | F21: Informational only
B22: Taxable interest (2b) | C22: =INDIRECT("Y"&Active_Year&"!J8") | D22: =INDIRECT("Y"&Active_Year&"!O8") | E22: =D22-C22
B23: Qualified dividends (info, 3a) | C23: =INDIRECT("Y"&Active_Year&"!J9") | D23: =INDIRECT("Y"&Active_Year&"!O9") | E23: =D23-C23 | F23: Stacks with LTCG
B24: Ordinary dividends (3b) | C24: =INDIRECT("Y"&Active_Year&"!J10") | D24: =INDIRECT("Y"&Active_Year&"!O10") | E24: =D24-C24
B25: Capital gain or (loss) (7) | C25: =INDIRECT("Y"&Active_Year&"!J11") | D25: =INDIRECT("Y"&Active_Year&"!O11") | E25: =D25-C25
B26: Other income / Sch 1 biz (8) | C26: =INDIRECT("Y"&Active_Year&"!J12") | D26: =INDIRECT("Y"&Active_Year&"!O12") | E26: =D26-C26 | F26: Business income via K-1, Sch C/E/F
B27: TOTAL INCOME (9) | C27: =INDIRECT("Y"&Active_Year&"!J13") | D27: =INDIRECT("Y"&Active_Year&"!O13") | E27: =D27-C27 | F27: Aggregator
B28: Adjustments to income (10) | C28: =INDIRECT("Y"&Active_Year&"!J14") | D28: =INDIRECT("Y"&Active_Year&"!O14") | E28: =D28-C28 | F28: Above-line deductions
B29: AGI (11) | C29: =INDIRECT("Y"&Active_Year&"!J15") | D29: =INDIRECT("Y"&Active_Year&"!O15") | E29: =D29-C29 | F29: Aggregator
B30: Std/Itemized deduction (12) | C30: =INDIRECT("Y"&Active_Year&"!J16") | D30: =INDIRECT("Y"&Active_Year&"!O16") | E30: =D30-C30
B31: QBI deduction (13) | C31: =INDIRECT("Y"&Active_Year&"!J17") | D31: =INDIRECT("Y"&Active_Year&"!O17") | E31: =D31-C31 | F31: §199A 20%
B32: TAXABLE INCOME (15) | C32: =INDIRECT("Y"&Active_Year&"!J18") | D32: =INDIRECT("Y"&Active_Year&"!O18") | E32: =D32-C32 | F32: Aggregator
B35: SECTION 3 — TAX COMPONENT SAVINGS
B37: Tax Component | C37: Without Planning | D37: With Planning | E37: Δ Savings | F37: Notes
B38: Ordinary Income Tax | C38: =INDIRECT("Y"&Active_Year&"!J97") | D38: =INDIRECT("Y"&Active_Year&"!K97") | E38: =C38-D38 | F38: Brackets x taxable income
B39: Capital Gains Tax | C39: =INDIRECT("Y"&Active_Year&"!J107") | D39: =INDIRECT("Y"&Active_Year&"!K107") | E39: =C39-D39 | F39: Preferential rate on LTCG/Qual Div
B40: Self-Employment Tax | C40: =INDIRECT("Y"&Active_Year&"!J80") | D40: =INDIRECT("Y"&Active_Year&"!K80") | E40: =C40-D40 | F40: 15.3% on SE earnings × 0.9235
B41: Payroll Tax (Employee + Employer) | C41: =INDIRECT("Y"&Active_Year&"!J91") | D41: =INDIRECT("Y"&Active_Year&"!K91") | E41: =C41-D41 | F41: FICA double-burden on owner W-2
B42: NIIT (3.8%) | C42: =INDIRECT("Y"&Active_Year&"!J114") | D42: =INDIRECT("Y"&Active_Year&"!K114") | E42: =C42-D42 | F42: On investment income above thresh
B43: Less: QBI Tax Benefit | C43: =INDIRECT("Y"&Active_Year&"!J131") | D43: =INDIRECT("Y"&Active_Year&"!K131") | E43: =C43-D43 | F43: §199A 20% deduction tax savings
B44: TOTAL FEDERAL TAX | C44: =INDIRECT("Y"&Active_Year&"!J133") | D44: =INDIRECT("Y"&Active_Year&"!K133") | E44: =C44-D44
B47: SECTION 4 — STRATEGY-BY-STRATEGY SAVINGS
B49: # | C49: Strategy | D49: Status | E49: Amount | F49: Marginal Savings
B50: #1 | C50: =INDIRECT("Y"&Active_Year&"!B6") | D50: =INDIRECT("Y"&Active_Year&"!E6") | E50: =IFERROR(INDIRECT("Y"&Active_Year&"!D6"),0) | F50: =IF(OR(INDIRECT("Y"&Active_Year&"!E6")="Committed",INDIRECT("Y"&Active_Year&"!E6")="Implemented"),-INDIRECT("Y"&Active_Year&"!D6")*0.32,0)
B51: #2 | C51: =INDIRECT("Y"&Active_Year&"!B7") | D51: =INDIRECT("Y"&Active_Year&"!E7") | E51: =IFERROR(INDIRECT("Y"&Active_Year&"!D7"),0) | F51: =IF(OR(INDIRECT("Y"&Active_Year&"!E7")="Committed",INDIRECT("Y"&Active_Year&"!E7")="Implemented"),-INDIRECT("Y"&Active_Year&"!D7")*0.32,0)
B52: #3 | C52: =INDIRECT("Y"&Active_Year&"!B8") | D52: =INDIRECT("Y"&Active_Year&"!E8") | E52: =IFERROR(INDIRECT("Y"&Active_Year&"!D8"),0) | F52: =IF(OR(INDIRECT("Y"&Active_Year&"!E8")="Committed",INDIRECT("Y"&Active_Year&"!E8")="Implemented"),-INDIRECT("Y"&Active_Year&"!D8")*0.32,0)
B53: #4 | C53: =INDIRECT("Y"&Active_Year&"!B9") | D53: =INDIRECT("Y"&Active_Year&"!E9") | E53: =IFERROR(INDIRECT("Y"&Active_Year&"!D9"),0) | F53: =IF(OR(INDIRECT("Y"&Active_Year&"!E9")="Committed",INDIRECT("Y"&Active_Year&"!E9")="Implemented"),-INDIRECT("Y"&Active_Year&"!D9")*0.32,0)
B54: #5 | C54: =INDIRECT("Y"&Active_Year&"!B10") | D54: =INDIRECT("Y"&Active_Year&"!E10") | E54: =IFERROR(INDIRECT("Y"&Active_Year&"!D10"),0) | F54: =IF(OR(INDIRECT("Y"&Active_Year&"!E10")="Committed",INDIRECT("Y"&Active_Year&"!E10")="Implemented"),-INDIRECT("Y"&Active_Year&"!D10")*0.32,0)
...

Sheet PY_Recon
B2: PY RECON — Baseline vs Filed Return
B3: Compares computed Baseline (tblMaster_Inputs) vs AsFiled (tblAsFiled) for Active_Year + Active_Client. Verify the engine before trusting roll-forward.
B5: Recon Year: | C5: 2025 | D5: Client: | E5: SAMPLE
B7: 1040 Line | C7: Description | D7: Computed (Baseline) | E7: Filed (AsFiled) | F7: Variance | G7: Status
B8: 1z | C8: Wages, salaries, tips | D8: =SUMIFS(tblMaster_Inputs[Baseline_Amount],tblMaster_Inputs[Year],$C$5,tblMaster_Inputs[ClientID],$E$5,tblMaster_Inputs[Primary_Line],"1z") | E8: =SUMIFS(tblAsFiled[Filed_Amount],tblAsFiled[Year],$C$5,tblAsFiled[ClientID],$E$5,tblAsFiled[Primary_Line],"1z") | F8: =D8-E8 | G8: =IF(ABS(F8)<1,"✓ OK","⚠ CHECK")
B9: 2b | C9: Taxable interest | D9: =SUMIFS(tblMaster_Inputs[Baseline_Amount],tblMaster_Inputs[Year],$C$5,tblMaster_Inputs[ClientID],$E$5,tblMaster_Inputs[Primary_Line],"2b") | E9: =SUMIFS(tblAsFiled[Filed_Amount],tblAsFiled[Year],$C$5,tblAsFiled[ClientID],$E$5,tblAsFiled[Primary_Line],"2b") | F9: =D9-E9 | G9: =IF(ABS(F9)<1,"✓ OK","⚠ CHECK")
B10: 3b | C10: Ordinary dividends | D10: =SUMIFS(tblMaster_Inputs[Baseline_Amount],tblMaster_Inputs[Year],$C$5,tblMaster_Inputs[ClientID],$E$5,tblMaster_Inputs[Primary_Line],"3b") | E10: =SUMIFS(tblAsFiled[Filed_Amount],tblAsFiled[Year],$C$5,tblAsFiled[ClientID],$E$5,tblAsFiled[Primary_Line],"3b") | F10: =D10-E10 | G10: =IF(ABS(F10)<1,"✓ OK","⚠ CHECK")
B11: 7 | C11: Capital gain or (loss) | D11: =SUMIFS(tblMaster_Inputs[Baseline_Amount],tblMaster_Inputs[Year],$C$5,tblMaster_Inputs[ClientID],$E$5,tblMaster_Inputs[Primary_Line],"7") | E11: =SUMIFS(tblAsFiled[Filed_Amount],tblAsFiled[Year],$C$5,tblAsFiled[ClientID],$E$5,tblAsFiled[Primary_Line],"7") | F11: =D11-E11 | G11: =IF(ABS(F11)<1,"✓ OK","⚠ CHECK")
B12: 8 | C12: Other income (Sch 1 — business) | D12: =SUMIFS(tblMaster_Inputs[Baseline_Amount],tblMaster_Inputs[Year],$C$5,tblMaster_Inputs[ClientID],$E$5,tblMaster_Inputs[Primary_Line],"8") | E12: =SUMIFS(tblAsFiled[Filed_Amount],tblAsFiled[Year],$C$5,tblAsFiled[ClientID],$E$5,tblAsFiled[Primary_Line],"8") | F12: =D12-E12 | G12: =IF(ABS(F12)<1,"✓ OK","⚠ CHECK")
B13: 9 | C13: TOTAL INCOME | D13: =SUM(D8:D12) | E13: =SUM(E8:E12) | F13: =D13-E13 | G13: =IF(ABS(F13)<1,"✓ OK","⚠ CHECK")
B14: 10 | C14: Adjustments to income | D14: =SUMIFS(tblMaster_Inputs[Baseline_Amount],tblMaster_Inputs[Year],$C$5,tblMaster_Inputs[ClientID],$E$5,tblMaster_Inputs[Primary_Line],"10") | E14: =SUMIFS(tblAsFiled[Filed_Amount],tblAsFiled[Year],$C$5,tblAsFiled[ClientID],$E$5,tblAsFiled[Primary_Line],"10") | F14: =D14-E14 | G14: =IF(ABS(F14)<1,"✓ OK","⚠ CHECK")
B15: 11 | C15: AGI | D15: =D13+D14 | E15: =E13+E14 | F15: =D15-E15 | G15: =IF(ABS(F15)<1,"✓ OK","⚠ CHECK")
B16: 12 | C16: Standard / Itemized deduction | D16: =SUMIFS(tblMaster_Inputs[Baseline_Amount],tblMaster_Inputs[Year],$C$5,tblMaster_Inputs[ClientID],$E$5,tblMaster_Inputs[Primary_Line],"12") | E16: =SUMIFS(tblAsFiled[Filed_Amount],tblAsFiled[Year],$C$5,tblAsFiled[ClientID],$E$5,tblAsFiled[Primary_Line],"12") | F16: =D16-E16 | G16: =IF(ABS(F16)<1,"✓ OK","⚠ CHECK")
B17: 13 | C17: QBI deduction | D17: =SUMIFS(tblMaster_Inputs[Baseline_Amount],tblMaster_Inputs[Year],$C$5,tblMaster_Inputs[ClientID],$E$5,tblMaster_Inputs[Primary_Line],"13") | E17: =SUMIFS(tblAsFiled[Filed_Amount],tblAsFiled[Year],$C$5,tblAsFiled[ClientID],$E$5,tblAsFiled[Primary_Line],"13") | F17: =D17-E17 | G17: =IF(ABS(F17)<1,"✓ OK","⚠ CHECK")
B18: 15 | C18: TAXABLE INCOME | D18: =D15+D16+D17 | E18: =E15+E16+E17 | F18: =D18-E18 | G18: =IF(ABS(F18)<1,"✓ OK","⚠ CHECK")
B20: RECON SUMMARY
B21: Lines matched: | C21: =COUNTIF(G8:G18,"✓ OK") | D21: of | E21: =COUNTA(G8:G18)
B22: Overall status: | C22: =IF(C21=E21,"✓ ALL LINES MATCH","⚠ VARIANCES FOUND — REVIEW BEFORE PLANNING")

Sheet Pivot_GPD
B2: PIVOT GETPIVOTDATA — Multi-Year Named Range Bridge
B3: Full year grid + Active_Year column (→ VP_ named ranges). GETPIVOTDATA pulls directly from visual pivots.
B5: INCOME BY 1040 LINE
B6: Named Range | C6: Description | D6: 2023 | E6: 2024 | F6: 2025 | G6: 2026 | H6: 2027 | I6: 2028 | J6: Active Year
B7: VP_Line_1z_Wages | C7: Wages (1z) | D7: =IFERROR(GETPIVOTDATA("Baseline_Amount",Visual_Pivot_Income!$B$5,"Primary_Line","1z","Year",2023),0) | E7: =IFERROR(GETPIVOTDATA("Baseline_Amount",Visual_Pivot_Income!$B$5,"Primary_Line","1z","Year",2024),0) | F7: =IFERROR(GETPIVOTDATA("Baseline_Amount",Visual_Pivot_Income!$B$5,"Primary_Line","1z","Year",2025),0) | G7: =IFERROR(GETPIVOTDATA("Baseline_Amount",Visual_Pivot_Income!$B$5,"Primary_Line","1z","Year",2026),0) | H7: =IFERROR(GETPIVOTDATA("Baseline_Amount",Visual_Pivot_Income!$B$5,"Primary_Line","1z","Year",2027),0) | I7: =IFERROR(GETPIVOTDATA("Baseline_Amount",Visual_Pivot_Income!$B$5,"Primary_Line","1z","Year",2028),0) | J7: =IFERROR(GETPIVOTDATA("Baseline_Amount",Visual_Pivot_Income!$B$5,"Primary_Line","1z","Year",Active_Year),0)
B8: VP_Line_2b_TaxInt | C8: Tax Interest (2b) | D8: =IFERROR(GETPIVOTDATA("Baseline_Amount",Visual_Pivot_Income!$B$5,"Primary_Line","2b","Year",2023),0) | E8: =IFERROR(GETPIVOTDATA("Baseline_Amount",Visual_Pivot_Income!$B$5,"Primary_Line","2b","Year",2024),0) | F8: =IFERROR(GETPIVOTDATA("Baseline_Amount",Visual_Pivot_Income!$B$5,"Primary_Line","2b","Year",2025),0) | G8: =IFERROR(GETPIVOTDATA("Baseline_Amount",Visual_Pivot_Income!$B$5,"Primary_Line","2b","Year",2026),0) | H8: =IFERROR(GETPIVOTDATA("Baseline_Amount",Visual_Pivot_Income!$B$5,"Primary_Line","2b","Year",2027),0) | I8: =IFERROR(GETPIVOTDATA("Baseline_Amount",Visual_Pivot_Income!$B$5,"Primary_Line","2b","Year",2028),0) | J8: =IFERROR(GETPIVOTDATA("Baseline_Amount",Visual_Pivot_Income!$B$5,"Primary_Line","2b","Year",Active_Year),0)
B9: VP_Line_3b_OrdDiv | C9: Ord Dividends (3b) | D9: =IFERROR(GETPIVOTDATA("Baseline_Amount",Visual_Pivot_Income!$B$5,"Primary_Line","3b","Year",2023),0) | E9: =IFERROR(GETPIVOTDATA("Baseline_Amount",Visual_Pivot_Income!$B$5,"Primary_Line","3b","Year",2024),0) | F9: =IFERROR(GETPIVOTDATA("Baseline_Amount",Visual_Pivot_Income!$B$5,"Primary_Line","3b","Year",2025),0) | G9: =IFERROR(GETPIVOTDATA("Baseline_Amount",Visual_Pivot_Income!$B$5,"Primary_Line","3b","Year",2026),0) | H9: =IFERROR(GETPIVOTDATA("Baseline_Amount",Visual_Pivot_Income!$B$5,"Primary_Line","3b","Year",2027),0) | I9: =IFERROR(GETPIVOTDATA("Baseline_Amount",Visual_Pivot_Income!$B$5,"Primary_Line","3b","Year",2028),0) | J9: =IFERROR(GETPIVOTDATA("Baseline_Amount",Visual_Pivot_Income!$B$5,"Primary_Line","3b","Year",Active_Year),0)
B10: VP_Line_7_CapGain | C10: Cap Gains (7) | D10: =IFERROR(GETPIVOTDATA("Baseline_Amount",Visual_Pivot_Income!$B$5,"Primary_Line","7","Year",2023),0) | E10: =IFERROR(GETPIVOTDATA("Baseline_Amount",Visual_Pivot_Income!$B$5,"Primary_Line","7","Year",2024),0) | F10: =IFERROR(GETPIVOTDATA("Baseline_Amount",Visual_Pivot_Income!$B$5,"Primary_Line","7","Year",2025),0) | G10: =IFERROR(GETPIVOTDATA("Baseline_Amount",Visual_Pivot_Income!$B$5,"Primary_Line","7","Year",2026),0) | H10: =IFERROR(GETPIVOTDATA("Baseline_Amount",Visual_Pivot_Income!$B$5,"Primary_Line","7","Year",2027),0) | I10: =IFERROR(GETPIVOTDATA("Baseline_Amount",Visual_Pivot_Income!$B$5,"Primary_Line","7","Year",2028),0) | J10: =IFERROR(GETPIVOTDATA("Baseline_Amount",Visual_Pivot_Income!$B$5,"Primary_Line","7","Year",Active_Year),0)
B11: VP_Line_8_OtherInc | C11: Business/Other (8) | D11: =IFERROR(GETPIVOTDATA("Baseline_Amount",Visual_Pivot_Income!$B$5,"Primary_Line","8","Year",2023),0) | E11: =IFERROR(GETPIVOTDATA("Baseline_Amount",Visual_Pivot_Income!$B$5,"Primary_Line","8","Year",2024),0) | F11: =IFERROR(GETPIVOTDATA("Baseline_Amount",Visual_Pivot_Income!$B$5,"Primary_Line","8","Year",2025),0) | G11: =IFERROR(GETPIVOTDATA("Baseline_Amount",Visual_Pivot_Income!$B$5,"Primary_Line","8","Year",2026),0) | H11: =IFERROR(GETPIVOTDATA("Baseline_Amount",Visual_Pivot_Income!$B$5,"Primary_Line","8","Year",2027),0) | I11: =IFERROR(GETPIVOTDATA("Baseline_Amount",Visual_Pivot_Income!$B$5,"Primary_Line","8","Year",2028),0) | J11: =IFERROR(GETPIVOTDATA("Baseline_Amount",Visual_Pivot_Income!$B$5,"Primary_Line","8","Year",Active_Year),0)
B12: VP_Line_12_Deduction | C12: Std/Item Ded (12) | D12: =IFERROR(GETPIVOTDATA("Baseline_Amount",Visual_Pivot_Income!$B$5,"Primary_Line","12","Year",2023),0) | E12: =IFERROR(GETPIVOTDATA("Baseline_Amount",Visual_Pivot_Income!$B$5,"Primary_Line","12","Year",2024),0) | F12: =IFERROR(GETPIVOTDATA("Baseline_Amount",Visual_Pivot_Income!$B$5,"Primary_Line","12","Year",2025),0) | G12: =IFERROR(GETPIVOTDATA("Baseline_Amount",Visual_Pivot_Income!$B$5,"Primary_Line","12","Year",2026),0) | H12: =IFERROR(GETPIVOTDATA("Baseline_Amount",Visual_Pivot_Income!$B$5,"Primary_Line","12","Year",2027),0) | I12: =IFERROR(GETPIVOTDATA("Baseline_Amount",Visual_Pivot_Income!$B$5,"Primary_Line","12","Year",2028),0) | J12: =IFERROR(GETPIVOTDATA("Baseline_Amount",Visual_Pivot_Income!$B$5,"Primary_Line","12","Year",Active_Year),0)
B13: VP_TotalIncome | C13: Grand Total | D13: =IFERROR(GETPIVOTDATA("Baseline_Amount",Visual_Pivot_Income!$B$5,"Year",2023),0) | E13: =IFERROR(GETPIVOTDATA("Baseline_Amount",Visual_Pivot_Income!$B$5,"Year",2024),0) | F13: =IFERROR(GETPIVOTDATA("Baseline_Amount",Visual_Pivot_Income!$B$5,"Year",2025),0) | G13: =IFERROR(GETPIVOTDATA("Baseline_Amount",Visual_Pivot_Income!$B$5,"Year",2026),0) | H13: =IFERROR(GETPIVOTDATA("Baseline_Amount",Visual_Pivot_Income!$B$5,"Year",2027),0) | I13: =IFERROR(GETPIVOTDATA("Baseline_Amount",Visual_Pivot_Income!$B$5,"Year",2028),0) | J13: =IFERROR(GETPIVOTDATA("Baseline_Amount",Visual_Pivot_Income!$B$5,"Year",Active_Year),0)
B15: HELPER CARVE-OUTS
B16: Named Range | C16: Description | D16: 2023 | E16: 2024 | F16: 2025 | G16: 2026 | H16: 2027 | I16: 2028 | J16: Active Year
B17: VP_OWNER_PAY | C17: Owner Wages | D17: =IFERROR(GETPIVOTDATA("Helper_Amount",Visual_Pivot_HelperCarveOuts!$B$5,"Helper_Treatment","OWNER_PAY","Year",2023),0) | E17: =IFERROR(GETPIVOTDATA("Helper_Amount",Visual_Pivot_HelperCarveOuts!$B$5,"Helper_Treatment","OWNER_PAY","Year",2024),0) | F17: =IFERROR(GETPIVOTDATA("Helper_Amount",Visual_Pivot_HelperCarveOuts!$B$5,"Helper_Treatment","OWNER_PAY","Year",2025),0) | G17: =IFERROR(GETPIVOTDATA("Helper_Amount",Visual_Pivot_HelperCarveOuts!$B$5,"Helper_Treatment","OWNER_PAY","Year",2026),0) | H17: =IFERROR(GETPIVOTDATA("Helper_Amount",Visual_Pivot_HelperCarveOuts!$B$5,"Helper_Treatment","OWNER_PAY","Year",2027),0) | I17: =IFERROR(GETPIVOTDATA("Helper_Amount",Visual_Pivot_HelperCarveOuts!$B$5,"Helper_Treatment","OWNER_PAY","Year",2028),0) | J17: =IFERROR(GETPIVOTDATA("Helper_Amount",Visual_Pivot_HelperCarveOuts!$B$5,"Helper_Treatment","OWNER_PAY","Year",Active_Year),0)
B18: VP_QUAL_DIV | C18: Qualified Dividends | D18: =IFERROR(GETPIVOTDATA("Helper_Amount",Visual_Pivot_HelperCarveOuts!$B$5,"Helper_Treatment","QUAL_DIV","Year",2023),0) | E18: =IFERROR(GETPIVOTDATA("Helper_Amount",Visual_Pivot_HelperCarveOuts!$B$5,"Helper_Treatment","QUAL_DIV","Year",2024),0) | F18: =IFERROR(GETPIVOTDATA("Helper_Amount",Visual_Pivot_HelperCarveOuts!$B$5,"Helper_Treatment","QUAL_DIV","Year",2025),0) | G18: =IFERROR(GETPIVOTDATA("Helper_Amount",Visual_Pivot_HelperCarveOuts!$B$5,"Helper_Treatment","QUAL_DIV","Year",2026),0) | H18: =IFERROR(GETPIVOTDATA("Helper_Amount",Visual_Pivot_HelperCarveOuts!$B$5,"Helper_Treatment","QUAL_DIV","Year",2027),0) | I18: =IFERROR(GETPIVOTDATA("Helper_Amount",Visual_Pivot_HelperCarveOuts!$B$5,"Helper_Treatment","QUAL_DIV","Year",2028),0) | J18: =IFERROR(GETPIVOTDATA("Helper_Amount",Visual_Pivot_HelperCarveOuts!$B$5,"Helper_Treatment","QUAL_DIV","Year",Active_Year),0)
B20: BUSINESS INCOME BY TREATMENT
B21: Named Range | C21: Description | D21: 2023 | E21: 2024 | F21: 2025 | G21: 2026 | H21: 2027 | I21: 2028 | J21: Active Year
B22: VP_BI_K1_SCorp_Active | C22: S-Corp K-1 Active | D22: =IFERROR(GETPIVOTDATA("Baseline_Amount",Visual_Pivot_BusinessIncome!$B$5,"Treatment_Profile","K1_SCorp_Active","Year",2023),0) | E22: =IFERROR(GETPIVOTDATA("Baseline_Amount",Visual_Pivot_BusinessIncome!$B$5,"Treatment_Profile","K1_SCorp_Active","Year",2024),0) | F22: =IFERROR(GETPIVOTDATA("Baseline_Amount",Visual_Pivot_BusinessIncome!$B$5,"Treatment_Profile","K1_SCorp_Active","Year",2025),0) | G22: =IFERROR(GETPIVOTDATA("Baseline_Amount",Visual_Pivot_BusinessIncome!$B$5,"Treatment_Profile","K1_SCorp_Active","Year",2026),0) | H22: =IFERROR(GETPIVOTDATA("Baseline_Amount",Visual_Pivot_BusinessIncome!$B$5,"Treatment_Profile","K1_SCorp_Active","Year",2027),0) | I22: =IFERROR(GETPIVOTDATA("Baseline_Amount",Visual_Pivot_BusinessIncome!$B$5,"Treatment_Profile","K1_SCorp_Active","Year",2028),0) | J22: =IFERROR(GETPIVOTDATA("Baseline_Amount",Visual_Pivot_BusinessIncome!$B$5,"Treatment_Profile","K1_SCorp_Active","Year",Active_Year),0)
B23: VP_BI_K1_PTP_Passive | C23: PTP K-1 Passive | D23: =IFERROR(GETPIVOTDATA("Baseline_Amount",Visual_Pivot_BusinessIncome!$B$5,"Treatment_Profile","K1_PTP_Passive","Year",2023),0) | E23: =IFERROR(GETPIVOTDATA("Baseline_Amount",Visual_Pivot_BusinessIncome!$B$5,"Treatment_Profile","K1_PTP_Passive","Year",2024),0) | F23: =IFERROR(GETPIVOTDATA("Baseline_Amount",Visual_Pivot_BusinessIncome!$B$5,"Treatment_Profile","K1_PTP_Passive","Year",2025),0) | G23: =IFERROR(GETPIVOTDATA("Baseline_Amount",Visual_Pivot_BusinessIncome!$B$5,"Treatment_Profile","K1_PTP_Passive","Year",2026),0) | H23: =IFERROR(GETPIVOTDATA("Baseline_Amount",Visual_Pivot_BusinessIncome!$B$5,"Treatment_Profile","K1_PTP_Passive","Year",2027),0) | I23: =IFERROR(GETPIVOTDATA("Baseline_Amount",Visual_Pivot_BusinessIncome!$B$5,"Treatment_Profile","K1_PTP_Passive","Year",2028),0) | J23: =IFERROR(GETPIVOTDATA("Baseline_Amount",Visual_Pivot_BusinessIncome!$B$5,"Treatment_Profile","K1_PTP_Passive","Year",Active_Year),0)
B24: VP_BI_SchE_Rental | C24: Sch E Rental | D24: =IFERROR(GETPIVOTDATA("Baseline_Amount",Visual_Pivot_BusinessIncome!$B$5,"Treatment_Profile","SchE_Rental","Year",2023),0) | E24: =IFERROR(GETPIVOTDATA("Baseline_Amount",Visual_Pivot_BusinessIncome!$B$5,"Treatment_Profile","SchE_Rental","Year",2024),0) | F24: =IFERROR(GETPIVOTDATA("Baseline_Amount",Visual_Pivot_BusinessIncome!$B$5,"Treatment_Profile","SchE_Rental","Year",2025),0) | G24: =IFERROR(GETPIVOTDATA("Baseline_Amount",Visual_Pivot_BusinessIncome!$B$5,"Treatment_Profile","SchE_Rental","Year",2026),0) | H24: =IFERROR(GETPIVOTDATA("Baseline_Amount",Visual_Pivot_BusinessIncome!$B$5,"Treatment_Profile","SchE_Rental","Year",2027),0) | I24: =IFERROR(GETPIVOTDATA("Baseline_Amount",Visual_Pivot_BusinessIncome!$B$5,"Treatment_Profile","SchE_Rental","Year",2028),0) | J24: =IFERROR(GETPIVOTDATA("Baseline_Amount",Visual_Pivot_BusinessIncome!$B$5,"Treatment_Profile","SchE_Rental","Year",Active_Year),0)
B25: VP_BI_Total | C25: Business Total | D25: =IFERROR(GETPIVOTDATA("Baseline_Amount",Visual_Pivot_BusinessIncome!$B$5,"Year",2023),0) | E25: =IFERROR(GETPIVOTDATA("Baseline_Amount",Visual_Pivot_BusinessIncome!$B$5,"Year",2024),0) | F25: =IFERROR(GETPIVOTDATA("Baseline_Amount",Visual_Pivot_BusinessIncome!$B$5,"Year",2025),0) | G25: =IFERROR(GETPIVOTDATA("Baseline_Amount",Visual_Pivot_BusinessIncome!$B$5,"Year",2026),0) | H25: =IFERROR(GETPIVOTDATA("Baseline_Amount",Visual_Pivot_BusinessIncome!$B$5,"Year",2027),0) | I25: =IFERROR(GETPIVOTDATA("Baseline_Amount",Visual_Pivot_BusinessIncome!$B$5,"Year",2028),0) | J25: =IFERROR(GETPIVOTDATA("Baseline_Amount",Visual_Pivot_BusinessIncome!$B$5,"Year",Active_Year),0)

Sheet Y2023
A1: Y2023 — standalone tax planning sandbox
A2: Strategies: enter Amount + Status below. Committed strategies flow to rollup M column. Push to Master_Inputs when final.
A4: ▸ STRATEGIES
A5: StrategyID | B5: Strategy Name | C5: TargetLine | D5: Amount | E5: Status | F5: Notes | G5: CounterLine | H5: Jeff_Ref_ID | I5: Line | J5: Description | K5: Baseline (Master) | L5: PY? | M5: S1 Override | N5: Strategies | O5: Effective | P5: Eff w/ Strategies | Q5: Drill
A6: STR-001 | B6: S-Corp Wage Optimization | C6: 1z | G6: 8 | H6: STD-008 | I6: 1z | J6: Wages | K6: =SUMIFS(tblMaster_Inputs[Baseline_Amount], tblMaster_Inputs[Year], 2023, tblMaster_Inputs[Primary_Line], $I6, tblMaster_Inputs[Activity_Type], "Baseline") | N6: =SUMIFS(tblY2023_Strategies[Amount],tblY2023_Strategies[TargetLine],$I6)-SUMIFS(tblY2023_Strategies[Amount],tblY2023_Strategies[CounterLine],$I6) | O6: =IF(UPPER(L6)="Y",SUMIFS(tblMaster_Inputs[Baseline_Amount],tblMaster_Inputs[Year],2022,tblMaster_Inputs[Primary_Line],"1z"),IF(ISBLANK(M6),K6,M6)) | P6: =O6+N6 | Q6: =HYPERLINK("#Y2023!I49", "↗ drill")
A7: STR-002 | B7: HSA Family Max | C7: 10 | H7: STD-001 | I7: 2a | J7: Tax-exempt interest (informational — Helper) | K7: =SUMIFS(tblMaster_Inputs[Helper_Amount], tblMaster_Inputs[Year], 2023, tblMaster_Inputs[Helper_Treatment], "TAX_EXEMPT") | N7: =SUMIFS(tblY2023_Strategies[Amount],tblY2023_Strategies[TargetLine],"2a",tblY2023_Strategies[Status],"Committed") | O7: =IF(UPPER(L7)="Y",SUMIFS(tblMaster_Inputs[Helper_Amount],tblMaster_Inputs[Year],2022,tblMaster_Inputs[Helper_Treatment],"TAX_EXEMPT"),IF(ISBLANK(M7),K7,M7)) | P7: =O7 | Q7: =HYPERLINK("#Y2023!I49", "↗ drill")
A8: STR-003 | B8: Charitable Bunching (DAF) | C8: 12 | H8: ADV-002 | I8: 2b | J8: Taxable interest | K8: =SUMIFS(tblMaster_Inputs[Baseline_Amount], tblMaster_Inputs[Year], 2023, tblMaster_Inputs[Primary_Line], $I8, tblMaster_Inputs[Activity_Type], "Baseline") | N8: =SUMIFS(tblY2023_Strategies[Amount],tblY2023_Strategies[TargetLine],$I8)-SUMIFS(tblY2023_Strategies[Amount],tblY2023_Strategies[CounterLine],$I8) | O8: =IF(UPPER(L8)="Y",SUMIFS(tblMaster_Inputs[Baseline_Amount],tblMaster_Inputs[Year],2022,tblMaster_Inputs[Primary_Line],"2b"),IF(ISBLANK(M8),K8,M8)) | P8: =O8+N8 | Q8: =HYPERLINK("#Y2023!I49", "↗ drill")
A9: STR-004 | B9: SEP-IRA / Solo 401(k) | C9: 8 | H9: STD-001 | I9: 3a | J9: Qualified dividends (informational — Helper) | K9: =SUMIFS(tblMaster_Inputs[Helper_Amount], tblMaster_Inputs[Year], 2023, tblMaster_Inputs[Helper_Treatment], "QUAL_DIV") | N9: =SUMIFS(tblY2023_Strategies[Amount],tblY2023_Strategies[TargetLine],"3a",tblY2023_Strategies[Status],"Committed") | O9: =IF(UPPER(L9)="Y",SUMIFS(tblMaster_Inputs[Helper_Amount],tblMaster_Inputs[Year],2022,tblMaster_Inputs[Helper_Treatment],"QUAL_DIV"),IF(ISBLANK(M9),K9,M9)) | P9: =O9 | Q9: =HYPERLINK("#Y2023!I49", "↗ drill")
A10: STR-005 | B10: Cost Seg Study | C10: 8 | H10: STD-012 | I10: 3b | J10: Ordinary dividends (total — incl qualified) | K10: =SUMIFS(tblMaster_Inputs[Baseline_Amount], tblMaster_Inputs[Year], 2023, tblMaster_Inputs[Primary_Line], $I10, tblMaster_Inputs[Activity_Type], "Baseline") | N10: =SUMIFS(tblY2023_Strategies[Amount],tblY2023_Strategies[TargetLine],$I10)-SUMIFS(tblY2023_Strategies[Amount],tblY2023_Strategies[CounterLine],$I10) | O10: =IF(UPPER(L10)="Y",SUMIFS(tblMaster_Inputs[Baseline_Amount],tblMaster_Inputs[Year],2022,tblMaster_Inputs[Primary_Line],"3b"),IF(ISBLANK(M10),K10,M10)) | P10: =O10+N10 | Q10: =HYPERLINK("#Y2023!I49", "↗ drill")
A11: STR-006 | B11: Roth Conversion | C11: 1z | H11: ADV-004 | I11: 7 | J11: Capital gain or (loss) | K11: =SUMIFS(tblMaster_Inputs[Baseline_Amount], tblMaster_Inputs[Year], 2023, tblMaster_Inputs[Primary_Line], $I11, tblMaster_Inputs[Activity_Type], "Baseline") | N11: =SUMIFS(tblY2023_Strategies[Amount],tblY2023_Strategies[TargetLine],$I11)-SUMIFS(tblY2023_Strategies[Amount],tblY2023_Strategies[CounterLine],$I11) | O11: =IF(UPPER(L11)="Y",SUMIFS(tblMaster_Inputs[Baseline_Amount],tblMaster_Inputs[Year],2022,tblMaster_Inputs[Primary_Line],"7"),IF(ISBLANK(M11),K11,M11)) | P11: =O11+N11 | Q11: =HYPERLINK("#Y2023!I49", "↗ drill")
A12: STR-007 | B12: Augusta Rule (§280A) | C12: 8 | H12: STD-002 | I12: 8 | J12: Other income (incl business income via Sch 1) | K12: =SUMIFS(tblMaster_Inputs[Baseline_Amount], tblMaster_Inputs[Year], 2023, tblMaster_Inputs[Primary_Line], $I12, tblMaster_Inputs[Activity_Type], "Baseline") | N12: =SUMIFS(tblY2023_Strategies[Amount],tblY2023_Strategies[TargetLine],$I12)-SUMIFS(tblY2023_Strategies[Amount],tblY2023_Strategies[CounterLine],$I12) | O12: =IF(UPPER(L12)="Y",SUMIFS(tblMaster_Inputs[Baseline_Amount],tblMaster_Inputs[Year],2022,tblMaster_Inputs[Primary_Line],"8"),IF(ISBLANK(M12),K12,M12)) | P12: =O12+N12 | Q12: =HYPERLINK("#Y2023!I49", "↗ drill")
A13: STR-008 | B13: Accountable Plan | C13: 8 | H13: STD-003 | I13: 9 | J13: TOTAL INCOME | K13: =K6+K8+K10+K11+K12 | N13: =N6+N8+N10+N11+N12 | O13: =O6+O8+O10+O11+O12 | P13: =P6+P8+P10+P11+P12 | Q13: =HYPERLINK("#Y2023!I49", "↗ drill")
A14: STR-009 | B14: Hire Children | C14: 8 | F14: Child wages reported on child's own return — counter-impact is cross-return, not within this 1040 | G14: 1z | H14: STD-005 | I14: 10 | J14: Adjustments to income | K14: =SUMIFS(tblMaster_Inputs[Baseline_Amount], tblMaster_Inputs[Year], 2023, tblMaster_Inputs[Primary_Line], $I14, tblMaster_Inputs[Activity_Type], "Baseline") | N14: =SUMIFS(tblY2023_Strategies[Amount],tblY2023_Strategies[TargetLine],$I14)-SUMIFS(tblY2023_Strategies[Amount],tblY2023_Strategies[CounterLine],$I14) | O14: =IF(UPPER(L14)="Y",SUMIFS(tblMaster_Inputs[Baseline_Amount],tblMaster_Inputs[Year],2022,tblMaster_Inputs[Primary_Line],"10"),IF(ISBLANK(M14),K14,M14)) | P14: =O14+N14 | Q14: =HYPERLINK("#Y2023!I49", "↗ drill")
A15: STR-010 | B15: Entity Restructuring | C15: 8 | G15: 1z | H15: STD-007 | I15: 11 | J15: AGI | K15: =K13+K14 | N15: =N13+N14 | O15: =O13+O14 | P15: =P13+P14 | Q15: =HYPERLINK("#Y2023!I49", "↗ drill")
A16: STR-011 | B16: Installment Sale / 1031 | C16: 7 | H16: STD-009 + ADV-006 | I16: 12 | J16: Std/Itemized deduction | K16: =SUMIFS(tblMaster_Inputs[Baseline_Amount], tblMaster_Inputs[Year], 2023, tblMaster_Inputs[Primary_Line], $I16, tblMaster_Inputs[Activity_Type], "Baseline") | N16: =SUMIFS(tblY2023_Strategies[Amount],tblY2023_Strategies[TargetLine],$I16)-SUMIFS(tblY2023_Strategies[Amount],tblY2023_Strategies[CounterLine],$I16) | O16: =IF(UPPER(L16)="Y",SUMIFS(tblMaster_Inputs[Baseline_Amount],tblMaster_Inputs[Year],2022,tblMaster_Inputs[Primary_Line],"12"),IF(ISBLANK(M16),K16,M16)) | P16: =O16+N16 | Q16: =HYPERLINK("#Y2023!I49", "↗ drill")
A17: STR-012 | B17: Bonus Depreciation §168(k) | C17: 8 | H17: STD-012 | I17: 13 | J17: QBI deduction | K17: =SUMIFS(tblMaster_Inputs[Baseline_Amount], tblMaster_Inputs[Year], 2023, tblMaster_Inputs[Primary_Line], $I17, tblMaster_Inputs[Activity_Type], "Baseline") | N17: =SUMIFS(tblY2023_Strategies[Amount],tblY2023_Strategies[TargetLine],$I17)-SUMIFS(tblY2023_Strategies[Amount],tblY2023_Strategies[CounterLine],$I17) | O17: =IF(UPPER(L17)="Y",SUMIFS(tblMaster_Inputs[Baseline_Amount],tblMaster_Inputs[Year],2022,tblMaster_Inputs[Primary_Line],"13"),IF(ISBLANK(M17),K17,M17)) | P17: =O17+N17 | Q17: =HYPERLINK("#Y2023!I49", "↗ drill")
A18: STR-013 | B18: R&D Credit §41 | C18: 13 | I18: 15 | J18: TAXABLE INCOME | K18: =K15+K16+K17 | N18: =N15+N16+N17 | O18: =O15+O16+O17 | P18: =P15+P16+P17 | Q18: =HYPERLINK("#Y2023!I49", "↗ drill")
A19: STR-014 | B19: SALT PTE Election | C19: 12
A20: STR-015 | B20: Timing / Deferral | C20: 8 | H20: STD-006
A22: ▸ TAX IMPACT SUMMARY | I22: Description | J22: Amount | K22: Effective | L22: Used by
A23: Metric | B23: Baseline | C23: Effective | D23: Eff w/ Strat | E23: Savings | I23: Owner W-2 wages | J23: =SUMIFS(tblMaster_Inputs[Baseline_Amount], tblMaster_Inputs[Year], 2023, tblMaster_Inputs[Treatment_Profile], "W2_SCorpOwner", tblMaster_Inputs[Activity_Type], "Baseline") | K23: =J23+SUMIFS(tblY2023_Strategies[Amount],tblY2023_Strategies[TargetLine],"1z")-SUMIFS(tblY2023_Strategies[Amount],tblY2023_Strategies[CounterLine],"1z") | L23: FICA/Employee
A24: Total Income | B24: =K13 | C24: =O13 | D24: =P13 | E24: =B24-D24 | I24: Third-party W-2 wages | J24: =SUMIFS(tblMaster_Inputs[Baseline_Amount], tblMaster_Inputs[Year], 2023, tblMaster_Inputs[Treatment_Profile], "W2_Employee", tblMaster_Inputs[Activity_Type], "Baseline") | K24: =J24 | L24: SE Tax sharing
A25: Taxable Income | B25: =K18 | C25: =O18 | D25: =P18 | E25: =B25-D25 | I25: Total W-2 wages | J25: =J23+J24 | K25: =K23+K24 | L25: SE Tax sharing
A26: Total Tax | B26: =J133 | C26: =J133 | D26: =K133 | E26: =B26-D26 | I26: Business income subject to SE | J26: =SUMIFS(tblMaster_Inputs[Baseline_Amount], tblMaster_Inputs[Year], 2023, tblMaster_Inputs[Bucket], "Business Income", tblMaster_Inputs[SE_Subject], "Yes", tblMaster_Inputs[Activity_Type], "Baseline") | K26: =J26 | L26: SE Tax base
A27: Effective Rate | B27: =J134 | C27: =J134 | D27: =K134 | E27: =B27-D27 | I27: Active business income NOT SE | J27: =SUMIFS(tblMaster_Inputs[Baseline_Amount], tblMaster_Inputs[Year], 2023, tblMaster_Inputs[Bucket], "Business Income", tblMaster_Inputs[SE_Subject], "No", tblMaster_Inputs[NIIT_Class], "Active", tblMaster_Inputs[Activity_Type], "Baseline") | K27: =J27+SUMIFS(tblY2023_Strategies[Amount],tblY2023_Strategies[TargetLine],"8")-SUMIFS(tblY2023_Strategies[Amount],tblY2023_Strategies[CounterLine],"8") | L27: NIIT/QBI
A28: Committed Strategies | B28: =COUNTIF(tblY2023_Strategies[Status],"Committed") | C28: Net Strategy Impact | D28: =SUMIF(tblY2023_Strategies[Status],"Committed",tblY2023_Strategies[Amount]) | I28: Passive business income/loss | J28: =SUMIFS(tblMaster_Inputs[Baseline_Amount], tblMaster_Inputs[Year], 2023, tblMaster_Inputs[Bucket], "Business Income", tblMaster_Inputs[NIIT_Class], "Passive", tblMaster_Inputs[Activity_Type], "Baseline") | K28: =J28 | L28: Passive Loss/NIIT
I29: Tax-exempt interest | J29: =SUMIFS(tblMaster_Inputs[Helper_Amount], tblMaster_Inputs[Year], 2023, tblMaster_Inputs[Helper_Treatment], "TAX_EXEMPT") | K29: =J29+SUMIFS(tblY2023_Strategies[Amount],tblY2023_Strategies[TargetLine],"2a")-SUMIFS(tblY2023_Strategies[Amount],tblY2023_Strategies[CounterLine],"2a") | L29: MAGI
I30: Qualified dividends carve-out | J30: =SUMIFS(tblMaster_Inputs[Helper_Amount], tblMaster_Inputs[Year], 2023, tblMaster_Inputs[Helper_Treatment], "QUAL_DIV", tblMaster_Inputs[Activity_Type], "Baseline") | K30: =J30 | L30: LTCG stacking
I31: Long-term capital gains | J31: =SUMIFS(tblMaster_Inputs[Baseline_Amount], tblMaster_Inputs[Year], 2023, tblMaster_Inputs[Treatment_Profile], "LTCG_Stock") + SUMIFS(tblMaster_Inputs[Baseline_Amount], tblMaster_Inputs[Year], 2023, tblMaster_Inputs[Treatment_Profile], "LTCG_RE") + SUMIFS(tblMaster_Inputs[Baseline_Amount], tblMaster_Inputs[Year], 2023, tblMaster_Inputs[Treatment_Profile], "LTCG_K1_Passthrough") + SUMIFS(tblMaster_Inputs[Baseline_Amount], tblMaster_Inputs[Year], 2023, tblMaster_Inputs[Treatment_Profile], "Sec1250_Recap", tblMaster_Inputs[Activity_Type], "Baseline") | K31: =J31+SUMIFS(tblY2023_Strategies[Amount],tblY2023_Strategies[TargetLine],"7")-SUMIFS(tblY2023_Strategies[Amount],tblY2023_Strategies[CounterLine],"7") | L31: Cap Gains Tax
I32: Short-term capital gains | J32: =SUMIFS(tblMaster_Inputs[Baseline_Amount], tblMaster_Inputs[Year], 2023, tblMaster_Inputs[Treatment_Profile], "STCG_Stock", tblMaster_Inputs[Activity_Type], "Baseline") | K32: =J32 | L32: Ordinary Tax
I33: §1250 unrecaptured gain | J33: =SUMIFS(tblMaster_Inputs[Helper_Amount], tblMaster_Inputs[Year], 2023, tblMaster_Inputs[Helper_Treatment], "SEC1250", tblMaster_Inputs[Activity_Type], "Baseline") | K33: =J33 | L33: 1250 Tax
I36: Description | J36: Value | K36: Effective | L36: Used by
I37: TI - LTCG - QUAL_DIV - SEC1250 | J37: =K18-J31-J30-J33 | K37: =P18-K31-K30-K33 | L37: Ordinary Tax
I38: AGI + tax-exempt interest | J38: =K15+J29 | K38: =P15+K29 | L38: NIIT
I39: Net investment income | J39: =K8+K10+K11+J28 | K39: =P8+P10+P11+K28 | L39: NIIT
I40: QBI-eligible business income | J40: =J26+J27 | K40: =K26+K27 | L40: QBI
I41: TI before QBI deduction | J41: =K15+K16 | K41: =P15+P16 | L41: QBI cap
I42: Net business loss | J42: =MIN(0,J26+J27+J28) | K42: =MIN(0,K26+K27+K28) | L42: EBL
I43: Net SE income | J43: =J26 | K43: =K26 | L43: SE Tax
K44: =J44
...

Sheet Y2024
A1: Y2024 — standalone tax planning sandbox
A2: Strategies: enter Amount + Status below. Committed strategies flow to rollup M column. Push to Master_Inputs when final.
A4: ▸ STRATEGIES
A5: StrategyID | B5: Strategy Name | C5: TargetLine | D5: Amount | E5: Status | F5: Notes | G5: CounterLine | H5: Jeff_Ref_ID | I5: Line | J5: Description | K5: Baseline (Master) | L5: PY? | M5: S1 Override | N5: Strategies | O5: Effective | P5: Eff w/ Strategies | Q5: Drill
A6: STR-001 | B6: S-Corp Wage Optimization | C6: 1z | G6: 8 | H6: STD-008 | I6: 1z | J6: Wages | K6: =SUMIFS(tblMaster_Inputs[Baseline_Amount],tblMaster_Inputs[Year],2024,tblMaster_Inputs[Primary_Line],$I6, tblMaster_Inputs[Activity_Type], "Baseline") | N6: =SUMIFS(tblY2024_Strategies[Amount],tblY2024_Strategies[TargetLine],$I6)-SUMIFS(tblY2024_Strategies[Amount],tblY2024_Strategies[CounterLine],$I6) | O6: =IF(UPPER(L6)="Y",SUMIFS(tblMaster_Inputs[Baseline_Amount],tblMaster_Inputs[Year],2023,tblMaster_Inputs[Primary_Line],"1z"),IF(ISBLANK(M6),K6,M6)) | P6: =O6+N6 | Q6: =HYPERLINK("#Y2024!I49", "↗ drill")
A7: STR-002 | B7: HSA Family Max | C7: 10 | H7: STD-001 | I7: 2a | J7: Tax-exempt interest (Helper) | K7: =SUMIFS(tblMaster_Inputs[Helper_Amount],tblMaster_Inputs[Year],2024,tblMaster_Inputs[Helper_Treatment],"TAX_EXEMPT") | N7: =SUMIFS(tblY2024_Strategies[Amount],tblY2024_Strategies[TargetLine],"2a",tblY2024_Strategies[Status],"Committed") | O7: =IF(UPPER(L7)="Y",SUMIFS(tblMaster_Inputs[Helper_Amount],tblMaster_Inputs[Year],2023,tblMaster_Inputs[Helper_Treatment],"TAX_EXEMPT"),IF(ISBLANK(M7),K7,M7)) | P7: =O7 | Q7: =HYPERLINK("#Y2024!I49", "↗ drill")
A8: STR-003 | B8: Charitable Bunching (DAF) | C8: 12 | H8: ADV-002 | I8: 2b | J8: Taxable interest | K8: =SUMIFS(tblMaster_Inputs[Baseline_Amount],tblMaster_Inputs[Year],2024,tblMaster_Inputs[Primary_Line],$I8, tblMaster_Inputs[Activity_Type], "Baseline") | N8: =SUMIFS(tblY2024_Strategies[Amount],tblY2024_Strategies[TargetLine],$I8)-SUMIFS(tblY2024_Strategies[Amount],tblY2024_Strategies[CounterLine],$I8) | O8: =IF(UPPER(L8)="Y",SUMIFS(tblMaster_Inputs[Baseline_Amount],tblMaster_Inputs[Year],2023,tblMaster_Inputs[Primary_Line],"2b"),IF(ISBLANK(M8),K8,M8)) | P8: =O8+N8 | Q8: =HYPERLINK("#Y2024!I49", "↗ drill")
A9: STR-004 | B9: SEP-IRA / Solo 401(k) | C9: 8 | H9: STD-001 | I9: 3a | J9: Qualified dividends (Helper) | K9: =SUMIFS(tblMaster_Inputs[Helper_Amount],tblMaster_Inputs[Year],2024,tblMaster_Inputs[Helper_Treatment],"QUAL_DIV") | N9: =SUMIFS(tblY2024_Strategies[Amount],tblY2024_Strategies[TargetLine],"3a",tblY2024_Strategies[Status],"Committed") | O9: =IF(UPPER(L9)="Y",SUMIFS(tblMaster_Inputs[Helper_Amount],tblMaster_Inputs[Year],2023,tblMaster_Inputs[Helper_Treatment],"QUAL_DIV"),IF(ISBLANK(M9),K9,M9)) | P9: =O9 | Q9: =HYPERLINK("#Y2024!I49", "↗ drill")
A10: STR-005 | B10: Cost Seg Study | C10: 8 | H10: STD-012 | I10: 3b | J10: Ordinary dividends | K10: =SUMIFS(tblMaster_Inputs[Baseline_Amount],tblMaster_Inputs[Year],2024,tblMaster_Inputs[Primary_Line],$I10, tblMaster_Inputs[Activity_Type], "Baseline") | N10: =SUMIFS(tblY2024_Strategies[Amount],tblY2024_Strategies[TargetLine],$I10)-SUMIFS(tblY2024_Strategies[Amount],tblY2024_Strategies[CounterLine],$I10) | O10: =IF(UPPER(L10)="Y",SUMIFS(tblMaster_Inputs[Baseline_Amount],tblMaster_Inputs[Year],2023,tblMaster_Inputs[Primary_Line],"3b"),IF(ISBLANK(M10),K10,M10)) | P10: =O10+N10 | Q10: =HYPERLINK("#Y2024!I49", "↗ drill")
A11: STR-006 | B11: Roth Conversion | C11: 1z | H11: ADV-004 | I11: 7 | J11: Capital gain or (loss) | K11: =SUMIFS(tblMaster_Inputs[Baseline_Amount],tblMaster_Inputs[Year],2024,tblMaster_Inputs[Primary_Line],$I11, tblMaster_Inputs[Activity_Type], "Baseline") | N11: =SUMIFS(tblY2024_Strategies[Amount],tblY2024_Strategies[TargetLine],$I11)-SUMIFS(tblY2024_Strategies[Amount],tblY2024_Strategies[CounterLine],$I11) | O11: =IF(UPPER(L11)="Y",SUMIFS(tblMaster_Inputs[Baseline_Amount],tblMaster_Inputs[Year],2023,tblMaster_Inputs[Primary_Line],"7"),IF(ISBLANK(M11),K11,M11)) | P11: =O11+N11 | Q11: =HYPERLINK("#Y2024!I49", "↗ drill")
A12: STR-007 | B12: Augusta Rule (§280A) | C12: 8 | H12: STD-002 | I12: 8 | J12: Other income (business via Sch 1) | K12: =SUMIFS(tblMaster_Inputs[Baseline_Amount],tblMaster_Inputs[Year],2024,tblMaster_Inputs[Primary_Line],$I12, tblMaster_Inputs[Activity_Type], "Baseline") | N12: =SUMIFS(tblY2024_Strategies[Amount],tblY2024_Strategies[TargetLine],$I12)-SUMIFS(tblY2024_Strategies[Amount],tblY2024_Strategies[CounterLine],$I12) | O12: =IF(UPPER(L12)="Y",SUMIFS(tblMaster_Inputs[Baseline_Amount],tblMaster_Inputs[Year],2023,tblMaster_Inputs[Primary_Line],"8"),IF(ISBLANK(M12),K12,M12)) | P12: =O12+N12 | Q12: =HYPERLINK("#Y2024!I49", "↗ drill")
A13: STR-008 | B13: Accountable Plan | C13: 8 | H13: STD-003 | I13: 9 | J13: TOTAL INCOME | K13: =K6+K8+K10+K11+K12 | N13: =N6+N8+N10+N11+N12 | O13: =O6+O8+O10+O11+O12 | P13: =P6+P8+P10+P11+P12 | Q13: =HYPERLINK("#Y2024!I49", "↗ drill")
A14: STR-009 | B14: Hire Children | C14: 8 | F14: Child wages reported on child's own return — counter-impact is cross-return, not within this 1040 | G14: 1z | H14: STD-005 | I14: 10 | J14: Adjustments to income | K14: =SUMIFS(tblMaster_Inputs[Baseline_Amount],tblMaster_Inputs[Year],2024,tblMaster_Inputs[Primary_Line],$I14, tblMaster_Inputs[Activity_Type], "Baseline") | N14: =SUMIFS(tblY2024_Strategies[Amount],tblY2024_Strategies[TargetLine],$I14)-SUMIFS(tblY2024_Strategies[Amount],tblY2024_Strategies[CounterLine],$I14) | O14: =IF(UPPER(L14)="Y",SUMIFS(tblMaster_Inputs[Baseline_Amount],tblMaster_Inputs[Year],2023,tblMaster_Inputs[Primary_Line],"10"),IF(ISBLANK(M14),K14,M14)) | P14: =O14+N14 | Q14: =HYPERLINK("#Y2024!I49", "↗ drill")
A15: STR-010 | B15: Entity Restructuring | C15: 8 | G15: 1z | H15: STD-007 | I15: 11 | J15: AGI | K15: =K13+K14 | N15: =N13+N14 | O15: =O13+O14 | P15: =P13+P14 | Q15: =HYPERLINK("#Y2024!I49", "↗ drill")
A16: STR-011 | B16: Installment Sale / 1031 | C16: 7 | H16: STD-009 + ADV-006 | I16: 12 | J16: Std/Itemized deduction | K16: =SUMIFS(tblMaster_Inputs[Baseline_Amount],tblMaster_Inputs[Year],2024,tblMaster_Inputs[Primary_Line],$I16, tblMaster_Inputs[Activity_Type], "Baseline") | N16: =SUMIFS(tblY2024_Strategies[Amount],tblY2024_Strategies[TargetLine],$I16)-SUMIFS(tblY2024_Strategies[Amount],tblY2024_Strategies[CounterLine],$I16) | O16: =IF(UPPER(L16)="Y",SUMIFS(tblMaster_Inputs[Baseline_Amount],tblMaster_Inputs[Year],2023,tblMaster_Inputs[Primary_Line],"12"),IF(ISBLANK(M16),K16,M16)) | P16: =O16+N16 | Q16: =HYPERLINK("#Y2024!I49", "↗ drill")
A17: STR-012 | B17: Bonus Depreciation §168(k) | C17: 8 | H17: STD-012 | I17: 13 | J17: QBI deduction | K17: =SUMIFS(tblMaster_Inputs[Baseline_Amount],tblMaster_Inputs[Year],2024,tblMaster_Inputs[Primary_Line],$I17, tblMaster_Inputs[Activity_Type], "Baseline") | N17: =SUMIFS(tblY2024_Strategies[Amount],tblY2024_Strategies[TargetLine],$I17)-SUMIFS(tblY2024_Strategies[Amount],tblY2024_Strategies[CounterLine],$I17) | O17: =IF(UPPER(L17)="Y",SUMIFS(tblMaster_Inputs[Baseline_Amount],tblMaster_Inputs[Year],2023,tblMaster_Inputs[Primary_Line],"13"),IF(ISBLANK(M17),K17,M17)) | P17: =O17+N17 | Q17: =HYPERLINK("#Y2024!I49", "↗ drill")
A18: STR-013 | B18: R&D Credit §41 | C18: 13 | I18: 15 | J18: TAXABLE INCOME | K18: =K15+K16+K17 | N18: =N15+N16+N17 | O18: =O15+O16+O17 | P18: =P15+P16+P17 | Q18: =HYPERLINK("#Y2024!I49", "↗ drill")
A19: STR-014 | B19: SALT PTE Election | C19: 12
A20: STR-015 | B20: Timing / Deferral | C20: 8 | H20: STD-006
A22: ▸ TAX IMPACT SUMMARY | I22: Description | J22: Amount | K22: Effective | L22: Used by
